Workbook
Name NativeTimeline_Join_Date: #N/A
Name Slicer_Age_Group: #N/A
Name Slicer_Country: #N/A
Name Slicer_Favorite_Genre: #N/A
Name Slicer_Price_Tier: #N/A

Sheet streaming_service_data - 
A1: User_ID | B1: User_Name | C1: Join_Date | D1: Last_Login | E1: Monthly_Price | F1: Watch_Hours | G1: Favorite_Genre | H1: Active_Devices | I1: Profile_Count | J1: Parental_Controls | K1: Total_Movies_Watched | L1: Total_Series_Watched | M1: Country | N1: Payment_Method | O1: Language_Preference | P1: Recommended_Content_Count | Q1: Average_Rating_Given | R1: Has_Downloaded_Content | S1: Membership_Status | T1: Loyalty_Points | U1: First_Device_Used | V1: Age_Group | W1: Primary_Watch_Time
A2: 2518 | B2: Amber | C2: 5/15/2023 | D2: 12/13/2024 | E2: 7.99 | F2: 49 | G2: Action | H2: 3 | I2: 6 | J2: TRUE | K2: 641 | L2: 117 | M2: USA | N2: PayPal | O2: Hindi | P2: 84 | Q2: 3.3 | R2: FALSE | S2: Active | T2: 2878 | U2: Smartphone | V2: 35-44 | W2: Late Night
A3: 6430 | B3: Patrick | C3: 44989 | D3: 12/15/2024 | E3: 7.99 | F3: 161 | G3: Drama | H3: 1 | I3: 2 | J3: TRUE | K3: 192 | L3: 65 | M3: USA | N3: PayPal | O3: German | P3: 69 | Q3: 4 | R3: FALSE | S3: Active | T3: 2291 | U3: Desktop | V3: 25-34 | W3: Evening
A4: 1798 | B4: Robert | C4: 44965 | D4: 12/14/2024 | E4: 11.99 | F4: 87 | G4: Action | H4: 2 | I4: 5 | J4: FALSE | K4: 260 | L4: 127 | M4: Canada | N4: Debit Card | O4: Mandarin | P4: 56 | Q4: 3.1 | R4: FALSE | S4: Active | T4: 1692 | U4: Desktop | V4: 35-44 | W4: Late Night
A5: 5255 | B5: Cole | C5: 1/31/2023 | D5: 45334 | E5: 15.99 | F5: 321 | G5: Sci-Fi | H5: 1 | I5: 5 | J5: FALSE | K5: 61 | L5: 192 | M5: UK | N5: Debit Card | O5: Mandarin | P5: 47 | Q5: 4.6 | R5: FALSE | S5: Active | T5: 952 | U5: Desktop | V5: 25-34 | W5: Evening
A6: 2854 | B6: Jamie | C6: 45083 | D6: 12/15/2024 | E6: 11.99 | F6: 386 | G6: Documentary | H6: 1 | I6: 4 | J6: TRUE | K6: 230 | L6: 2 | M6: USA | N6: PayPal | O6: Mandarin | P6: 39 | Q6: 3.7 | R6: FALSE | S6: Active | T6: 1823 | U6: Desktop | V6: 25-34 | W6: Late Night
A7: 6735 | B7: Mary | C7: 9/17/2023 | D7: 11/19/2024 | E7: 15.99 | F7: 408 | G7: Documentary | H7: 2 | I7: 6 | J7: TRUE | K7: 837 | L7: 105 | M7: India | N7: Credit Card | O7: Spanish | P7: 71 | Q7: 4.3 | R7: TRUE | S7: Active | T7: 33 | U7: Smart TV | V7: 18-24 | W7: Morning
A8: 2995 | B8: Theodore | C8: 8/25/2024 | D8: 45577 | E8: 7.99 | F8: 475 | G8: Horror | H8: 5 | I8: 4 | J8: TRUE | K8: 510 | L8: 143 | M8: USA | N8: Credit Card | O8: English | P8: 1 | Q8: 4.5 | R8: FALSE | S8: Active | T8: 755 | U8: Laptop | V8: 35-44 | W8: Late Night
A9: 5120 | B9: Olivia | C9: 5/31/2024 | D9: 12/14/2024 | E9: 15.99 | F9: 258 | G9: Action | H9: 4 | I9: 1 | J9: TRUE | K9: 907 | L9: 47 | M9: Australia | N9: Debit Card | O9: Hindi | P9: 32 | Q9: 3.7 | R9: TRUE | S9: Active | T9: 2866 | U9: Smartphone | V9: 45-54 | W9: Late Night
A10: 6063 | B10: Patricia | C10: 6/17/2023 | D10: 12/17/2024 | E10: 15.99 | F10: 183 | G10: Comedy | H10: 5 | I10: 2 | J10: TRUE | K10: 676 | L10: 61 | M10: Germany | N10: Cryptocurrency | O10: Mandarin | P10: 26 | Q10: 3.3 | R10: TRUE | S10: Active | T10: 336 | U10: Tablet | V10: 25-34 | W10: Late Night
A11: 6896 | B11: Linda | C11: 44969 | D11: 12/14/2024 | E11: 7.99 | F11: 164 | G11: Documentary | H11: 5 | I11: 4 | J11: TRUE | K11: 406 | L11: 79 | M11: USA | N11: Credit Card | O11: French | P11: 90 | Q11: 3.2 | R11: FALSE | S11: Active | T11: 3898 | U11: Laptop | V11: 55+ | W11: Late Night
A12: 8447 | B12: Nichole | C12: 3/28/2023 | D12: 11/22/2024 | E12: 11.99 | F12: 411 | G12: Comedy | H12: 5 | I12: 4 | J12: TRUE | K12: 352 | L12: 78 | M12: UK | N12: Credit Card | O12: English | P12: 47 | Q12: 3.7 | R12: FALSE | S12: Active | T12: 650 | U12: Tablet | V12: 55+ | W12: Late Night
A13: 1433 | B13: Frances | C13: 45325 | D13: 11/20/2024 | E13: 15.99 | F13: 160 | G13: Drama | H13: 5 | I13: 6 | J13: TRUE | K13: 391 | L13: 132 | M13: Canada | N13: Debit Card | O13: German | P13: 57 | Q13: 3 | R13: FALSE | S13: Active | T13: 185 | U13: Laptop | V13: 35-44 | W13: Late Night
A14: 4511 | B14: Maurice | C14: 3/27/2023 | D14: 11/25/2024 | E14: 7.99 | F14: 348 | G14: Drama | H14: 2 | I14: 5 | J14: FALSE | K14: 501 | L14: 71 | M14: Germany | N14: Debit Card | O14: French | P14: 38 | Q14: 4.3 | R14: FALSE | S14: Active | T14: 1547 | U14: Smartphone | V14: 45-54 | W14: Late Night
A15: 9966 | B15: Jennifer | C15: 9/15/2024 | D15: 11/30/2024 | E15: 7.99 | F15: 451 | G15: Documentary | H15: 3 | I15: 1 | J15: FALSE | K15: 995 | L15: 164 | M15: UK | N15: Cryptocurrency | O15: English | P15: 62 | Q15: 3 | R15: TRUE | S15: Active | T15: 3788 | U15: Smartphone | V15: 18-24 | W15: Late Night
A16: 7093 | B16: Cheryl | C16: 45113 | D16: 45608 | E16: 7.99 | F16: 69 | G16: Documentary | H16: 2 | I16: 5 | J16: FALSE | K16: 222 | L16: 13 | M16: France | N16: PayPal | O16: German | P16: 0 | Q16: 4.7 | R16: TRUE | S16: Active | T16: 1051 | U16: Desktop | V16: 18-24 | W16: Afternoon
A17: 4351 | B17: Kathy | C17: 5/18/2024 | D17: 11/30/2024 | E17: 11.99 | F17: 166 | G17: Horror | H17: 1 | I17: 6 | J17: TRUE | K17: 788 | L17: 31 | M17: USA | N17: PayPal | O17: German | P17: 25 | Q17: 4.3 | R17: TRUE | S17: Active | T17: 633 | U17: Smart TV | V17: 35-44 | W17: Afternoon
A18: 6007 | B18: Cassie | C18: 2/14/2023 | D18: 12/17/2024 | E18: 7.99 | F18: 449 | G18: Horror | H18: 2 | I18: 4 | J18: TRUE | K18: 369 | L18: 25 | M18: Germany | N18: Debit Card | O18: Spanish | P18: 65 | Q18: 4.6 | R18: FALSE | S18: Active | T18: 4133 | U18: Smartphone | V18: 25-34 | W18: Evening
A19: 9710 | B19: Charles | C19: 44963 | D19: 11/27/2024 | E19: 7.99 | F19: 441 | G19: Romance | H19: 1 | I19: 5 | J19: FALSE | K19: 228 | L19: 39 | M19: Germany | N19: PayPal | O19: Mandarin | P19: 50 | Q19: 3.1 | R19: TRUE | S19: Active | T19: 1159 | U19: Desktop | V19: 35-44 | W19: Morning
A20: 9034 | B20: William | C20: 9/20/2023 | D20: 12/18/2024 | E20: 15.99 | F20: 224 | G20: Comedy | H20: 1 | I20: 5 | J20: TRUE | K20: 827 | L20: 138 | M20: Canada | N20: Debit Card | O20: Mandarin | P20: 11 | Q20: 4.5 | R20: TRUE | S20: Active | T20: 4673 | U20: Tablet | V20: 18-24 | W20: Afternoon
A21: 6197 | B21: Tiffany | C21: 44992 | D21: 11/28/2024 | E21: 15.99 | F21: 44 | G21: Action | H21: 2 | I21: 4 | J21: FALSE | K21: 983 | L21: 145 | M21: India | N21: PayPal | O21: French | P21: 78 | Q21: 3 | R21: FALSE | S21: Active | T21: 4200 | U21: Laptop | V21: 45-54 | W21: Evening
A22: 2820 | B22: Mark | C22: 7/15/2023 | D22: 45303 | E22: 7.99 | F22: 202 | G22: Drama | H22: 1 | I22: 5 | J22: TRUE | K22: 109 | L22: 41 | M22: USA | N22: Cryptocurrency | O22: Spanish | P22: 42 | Q22: 4.6 | R22: FALSE | S22: Active | T22: 3607 | U22: Desktop | V22: 35-44 | W22: Late Night
A23: 1101 | B23: Mary | C23: 6/13/2024 | D23: 11/23/2024 | E23: 15.99 | F23: 39 | G23: Horror | H23: 2 | I23: 3 | J23: TRUE | K23: 181 | L23: 128 | M23: Australia | N23: PayPal | O23: Mandarin | P23: 3 | Q23: 4.5 | R23: TRUE | S23: Active | T23: 4602 | U23: Smart TV | V23: 55+ | W23: Evening
A24: 1650 | B24: Charles | C24: 8/25/2024 | D24: 11/23/2024 | E24: 15.99 | F24: 319 | G24: Romance | H24: 2 | I24: 2 | J24: FALSE | K24: 842 | L24: 145 | M24: France | N24: Cryptocurrency | O24: Mandarin | P24: 27 | Q24: 3.6 | R24: TRUE | S24: Active | T24: 256 | U24: Smart TV | V24: 35-44 | W24: Afternoon
A25: 4884 | B25: Anne | C25: 11/19/2023 | D25: 11/25/2024 | E25: 15.99 | F25: 150 | G25: Sci-Fi | H25: 3 | I25: 3 | J25: TRUE | K25: 40 | L25: 196 | M25: Canada | N25: Debit Card | O25: German | P25: 60 | Q25: 3.7 | R25: FALSE | S25: Active | T25: 2406 | U25: Laptop | V25: 55+ | W25: Evening
A26: 8321 | B26: Carol | C26: 9/22/2023 | D26: 11/23/2024 | E26: 11.99 | F26: 496 | G26: Romance | H26: 3 | I26: 1 | J26: TRUE | K26: 431 | L26: 41 | M26: India | N26: Credit Card | O26: English | P26: 91 | Q26: 4 | R26: TRUE | S26: Active | T26: 1394 | U26: Smart TV | V26: 55+ | W26: Afternoon
A27: 2381 | B27: Cynthia | C27: 5/15/2024 | D27: 12/15/2024 | E27: 7.99 | F27: 347 | G27: Horror | H27: 2 | I27: 5 | J27: FALSE | K27: 415 | L27: 194 | M27: USA | N27: Credit Card | O27: German | P27: 76 | Q27: 4.3 | R27: TRUE | S27: Active | T27: 1856 | U27: Desktop | V27: 18-24 | W27: Afternoon
A28: 9507 | B28: Destiny | C28: 6/19/2023 | D28: 11/19/2024 | E28: 11.99 | F28: 201 | G28: Action | H28: 1 | I28: 6 | J28: TRUE | K28: 902 | L28: 86 | M28: USA | N28: Cryptocurrency | O28: French | P28: 69 | Q28: 4.9 | R28: TRUE | S28: Active | T28: 1665 | U28: Smart TV | V28: 18-24 | W28: Afternoon
A29: 2851 | B29: Brittany | C29: 5/22/2024 | D29: 11/23/2024 | E29: 15.99 | F29: 415 | G29: Romance | H29: 3 | I29: 5 | J29: TRUE | K29: 769 | L29: 144 | M29: Australia | N29: Cryptocurrency | O29: Spanish | P29: 98 | Q29: 3.9 | R29: FALSE | S29: Active | T29: 2759 | U29: Tablet | V29: 35-44 | W29: Evening
A30: 4083 | B30: Amy | C30: 1/30/2024 | D30: 45577 | E30: 11.99 | F30: 32 | G30: Horror | H30: 1 | I30: 4 | J30: TRUE | K30: 588 | L30: 137 | M30: France | N30: Credit Card | O30: English | P30: 85 | Q30: 3.7 | R30: TRUE | S30: Active | T30: 3433 | U30: Laptop | V30: 35-44 | W30: Afternoon
A31: 4608 | B31: Kimberly | C31: 3/28/2024 | D31: 11/28/2024 | E31: 11.99 | F31: 338 | G31: Comedy | H31: 3 | I31: 2 | J31: TRUE | K31: 528 | L31: 184 | M31: UK | N31: Cryptocurrency | O31: Spanish | P31: 58 | Q31: 3.7 | R31: TRUE | S31: Active | T31: 3966 | U31: Desktop | V31: 55+ | W31: Late Night
A32: 4815 | B32: Ariel | C32: 45329 | D32: 11/20/2024 | E32: 7.99 | F32: 52 | G32: Documentary | H32: 5 | I32: 5 | J32: FALSE | K32: 467 | L32: 23 | M32: USA | N32: PayPal | O32: Spanish | P32: 97 | Q32: 3.3 | R32: TRUE | S32: Active | T32: 4185 | U32: Desktop | V32: 55+ | W32: Evening
A33: 9597 | B33: Lauren | C33: 45455 | D33: 45334 | E33: 11.99 | F33: 447 | G33: Romance | H33: 5 | I33: 5 | J33: FALSE | K33: 73 | L33: 138 | M33: Germany | N33: Debit Card | O33: Hindi | P33: 84 | Q33: 4.1 | R33: FALSE | S33: Active | T33: 784 | U33: Smartphone | V33: 25-34 | W33: Afternoon
A34: 6566 | B34: Joshua | C34: 6/22/2023 | D34: 12/17/2024 | E34: 11.99 | F34: 312 | G34: Horror | H34: 5 | I34: 1 | J34: TRUE | K34: 895 | L34: 154 | M34: Germany | N34: Debit Card | O34: Spanish | P34: 85 | Q34: 4.7 | R34: TRUE | S34: Active | T34: 3428 | U34: Laptop | V34: 25-34 | W34: Evening
A35: 1419 | B35: Megan | C35: 44992 | D35: 12/16/2024 | E35: 11.99 | F35: 406 | G35: Sci-Fi | H35: 2 | I35: 6 | J35: FALSE | K35: 983 | L35: 113 | M35: India | N35: Cryptocurrency | O35: German | P35: 78 | Q35: 3.1 | R35: FALSE | S35: Active | T35: 4245 | U35: Smartphone | V35: 25-34 | W35: Evening
A36: 9470 | B36: Stephanie | C36: 11/28/2023 | D36: 12/15/2024 | E36: 7.99 | F36: 350 | G36: Horror | H36: 3 | I36: 6 | J36: TRUE | K36: 801 | L36: 156 | M36: France | N36: Credit Card | O36: Mandarin | P36: 66 | Q36: 4.6 | R36: TRUE | S36: Active | T36: 2580 | U36: Smart TV | V36: 18-24 | W36: Late Night
A37: 4989 | B37: Terrence | C37: 45566 | D37: 45577 | E37: 7.99 | F37: 99 | G37: Comedy | H37: 2 | I37: 5 | J37: TRUE | K37: 96 | L37: 114 | M37: USA | N37: PayPal | O37: Hindi | P37: 45 | Q37: 4.3 | R37: FALSE | S37: Active | T37: 2779 | U37: Smart TV | V37: 55+ | W37: Morning
A38: 9389 | B38: Julia | C38: 45361 | D38: 11/21/2024 | E38: 15.99 | F38: 53 | G38: Sci-Fi | H38: 1 | I38: 2 | J38: FALSE | K38: 849 | L38: 98 | M38: India | N38: Credit Card | O38: Mandarin | P38: 14 | Q38: 3.1 | R38: FALSE | S38: Active | T38: 2318 | U38: Smartphone | V38: 35-44 | W38: Evening
A39: 7728 | B39: Derrick | C39: 9/15/2023 | D39: 12/13/2024 | E39: 11.99 | F39: 484 | G39: Romance | H39: 3 | I39: 6 | J39: FALSE | K39: 515 | L39: 174 | M39: UK | N39: PayPal | O39: German | P39: 12 | Q39: 4 | R39: TRUE | S39: Active | T39: 827 | U39: Smartphone | V39: 25-34 | W39: Morning
A40: 7943 | B40: Nathan | C40: 45301 | D40: 45303 | E40: 15.99 | F40: 211 | G40: Documentary | H40: 2 | I40: 6 | J40: TRUE | K40: 657 | L40: 137 | M40: Australia | N40: Credit Card | O40: Hindi | P40: 26 | Q40: 4 | R40: TRUE | S40: Active | T40: 2670 | U40: Desktop | V40: 18-24 | W40: Late Night
...

Sheet Data Anomalies -Pls Read It
A2: Notes To Be Focused - Data Anomalies
A4: Error | B4: There are 19 Users above where if you see the Join Date & Last Login shows negative value as the Join date can not be higher than the Last login date
A5: Fixes | B5: Hence I've swapped the last login date and join date to process with report buliding
A7: Error | B7: User ID 4115 - You can see the Join Date & Last Login Date shows the same date, however wathced hours show as 158 which is not technically possible in the real life as 1 day only have 24 hours.
A8: Fixes | B8: I've updated the Last Login date greater by 1 month from Joined Date to process with report building
A10: Notes to be considered - Additional Column Created | P10: Y axis | Q10: Have used this in Heat Map - Just for presentation
P11: 40 | Q11: _40
A12: Sr. No. | B12: Coloumn Name | C12: Logic Used | D12: Fomula Used | P12: 39
A13: 1 | B13: Tenure Days | C13: Last Login - Joined Date | D13: Substraction | P13: 38 | Q13: _38
A14: 2 | B14: Price Tier | C14: Given Names To Subsciption Prices - Basic - 7.99, Standard - 11.99, & Premium - 15.99 | D14: IFS Formula | P14: 37
A15: 3 | B15: Watch HR per Week | C15: Weekly Watching Hours / Weekly Viewing Frequency = (Average Watch Hours normalized by Tenure). | P15: 36 | Q15: _36
A16: 4 | B16: Frequency Bucket | C16: We have used three type of users "Casual" who watch 0-5 hours watch time in a week, "Regular" who watch 5-15 hours watch time in a week & "Power" who watch 15+ hours watch time in a week. | D16: Have used IF formula and above Avg Hrs/WK formula together | P16: 35
A17: 5 | B17: Per Day Watch Hr | C17: Per Day Watching Hours = Watching Hours / Total number of Movies + Total Number of Series | D17: Maths Formula - Divison | E17: This values were not used in report as there was not specific ask in the questions but it can give a good business insights | P17: 34 | Q17: _34
A18: 6 | B18: BR/VW | C18: As We get per day Watch Hour, So have used a logic where if a user is having less than 9 Miutes (0.15 hr) watch time average We've considered it as "Browser" who just comes and check the show and goes back but don't consume the whole content, And second is the "Viewer" who is having more than 9 minutes watch time average Cause that user have spent some time in content consuming. | D18: IFS formula with above Per Day Watch HR | E18: This values were not used in report as there was not specific ask in the questions but it can give a good business insights | P18: 33
P19: 32 | Q19: _32
P20: 31
A21: User_ID | B21: User_Name | C21: Join_Date | D21: Last_Login | E21: Monthly_Price | F21: Watch_Hours | G21: Favorite_Genre | H21: Active_Devices | I21: Profile_Count | J21: Parental_Controls | K21: Total_Movies_Watched | L21: Total_Series_Watched | M21: Country | N21: Payment_Method | O21: Language_Preference | P21: Recommended_Content_Count | Q21: Average_Rating_Given | R21: Has_Downloaded_Content | S21: Membership_Status | T21: Loyalty_Points | U21: First_Device_Used | V21: Age_Group | W21: Primary_Watch_Time | X21: Tenure Days | Y21: Price Tier | Z21: Login Frequence Per Week | AA21: Changes Done
A22: 9597 | B22: Lauren | C22: 45632 | D22: 45628 | E22: 11.99 | F22: 447 | G22: Romance | H22: 5 | I22: 5 | J22: FALSE | K22: 73 | L22: 138 | M22: Germany | N22: Debit Card | O22: Hindi | P22: 84 | Q22: 4.1 | R22: FALSE | S22: Active | T22: 784 | U22: Smartphone | V22: 25-34 | W22: Afternoon | X22: -4 | Y22: STANDARD | Z22: -782.25 | AA22: Swapped Join Date & Last Login Date
A23: 4668 | B23: Carly | C23: 45643 | D23: 45635 | E23: 11.99 | F23: 396 | G23: Sci-Fi | H23: 5 | I23: 5 | J23: TRUE | K23: 549 | L23: 35 | M23: Canada | N23: PayPal | O23: German | P23: 66 | Q23: 3.6 | R23: TRUE | S23: Active | T23: 4293 | U23: Laptop | V23: 55+ | W23: Morning | X23: -8 | Y23: STANDARD | Z23: -346.5 | AA23: Swapped Join Date & Last Login Date
A24: 8068 | B24: Carolyn | C24: 45640 | D24: 45619 | E24: 15.99 | F24: 77 | G24: Drama | H24: 5 | I24: 3 | J24: FALSE | K24: 780 | L24: 138 | M24: India | N24: Cryptocurrency | O24: French | P24: 66 | Q24: 3.4 | R24: FALSE | S24: Active | T24: 1752 | U24: Tablet | V24: 18-24 | W24: Afternoon | X24: -21 | Y24: PREMIUM | Z24: -25.666667 | AA24: Swapped Join Date & Last Login Date
A25: 1003 | B25: Vickie | C25: 45638 | D25: 45618 | E25: 11.99 | F25: 433 | G25: Horror | H25: 5 | I25: 4 | J25: FALSE | K25: 350 | L25: 2 | M25: Germany | N25: Cryptocurrency | O25: Spanish | P25: 41 | Q25: 3.1 | R25: TRUE | S25: Active | T25: 2043 | U25: Smartphone | V25: 35-44 | W25: Late Night | X25: -20 | Y25: STANDARD | Z25: -151.55 | AA25: Swapped Join Date & Last Login Date
A26: 1284 | B26: Michael | C26: 45630 | D26: 45627 | E26: 7.99 | F26: 405 | G26: Comedy | H26: 4 | I26: 3 | J26: TRUE | K26: 695 | L26: 85 | M26: Australia | N26: Credit Card | O26: French | P26: 42 | Q26: 3.7 | R26: FALSE | S26: Active | T26: 2395 | U26: Laptop | V26: 25-34 | W26: Morning | X26: -3 | Y26: BASIC | Z26: -945 | AA26: Swapped Join Date & Last Login Date
A27: 3633 | B27: Randy | C27: 45644 | D27: 45636 | E27: 7.99 | F27: 176 | G27: Action | H27: 5 | I27: 1 | J27: TRUE | K27: 936 | L27: 11 | M27: France | N27: Cryptocurrency | O27: English | P27: 42 | Q27: 3.2 | R27: FALSE | S27: Active | T27: 4414 | U27: Smartphone | V27: 35-44 | W27: Late Night | X27: -8 | Y27: BASIC | Z27: -154 | AA27: Swapped Join Date & Last Login Date
A28: 7484 | B28: Bradley | C28: 45634 | D28: 45617 | E28: 11.99 | F28: 152 | G28: Romance | H28: 5 | I28: 1 | J28: FALSE | K28: 623 | L28: 180 | M28: Canada | N28: Cryptocurrency | O28: French | P28: 89 | Q28: 4.5 | R28: TRUE | S28: Active | T28: 1594 | U28: Smartphone | V28: 25-34 | W28: Late Night | X28: -17 | Y28: STANDARD | Z28: -62.588235 | AA28: Swapped Join Date & Last Login Date
A29: 5083 | B29: Lisa | C29: 45620 | D29: 45619 | E29: 15.99 | F29: 19 | G29: Romance | H29: 3 | I29: 2 | J29: TRUE | K29: 781 | L29: 179 | M29: Canada | N29: Debit Card | O29: German | P29: 8 | Q29: 4.3 | R29: FALSE | S29: Active | T29: 1525 | U29: Laptop | V29: 45-54 | W29: Evening | X29: -1 | Y29: PREMIUM | Z29: -133 | AA29: Swapped Join Date & Last Login Date
A30: 3781 | B30: Jasmine | C30: 45643 | D30: 45625 | E30: 15.99 | F30: 249 | G30: Romance | H30: 1 | I30: 4 | J30: TRUE | K30: 713 | L30: 125 | M30: UK | N30: PayPal | O30: German | P30: 95 | Q30: 4.8 | R30: FALSE | S30: Active | T30: 74 | U30: Laptop | V30: 18-24 | W30: Morning | X30: -18 | Y30: PREMIUM | Z30: -96.833333 | AA30: Swapped Join Date & Last Login Date
A31: 9239 | B31: Daniel | C31: 45621 | D31: 45617 | E31: 15.99 | F31: 274 | G31: Drama | H31: 5 | I31: 6 | J31: FALSE | K31: 732 | L31: 105 | M31: UK | N31: PayPal | O31: Hindi | P31: 36 | Q31: 4.1 | R31: TRUE | S31: Active | T31: 4194 | U31: Smart TV | V31: 45-54 | W31: Evening | X31: -4 | Y31: PREMIUM | Z31: -479.5 | AA31: Swapped Join Date & Last Login Date
A32: 8923 | B32: Douglas | C32: 45637 | D32: 45636 | E32: 11.99 | F32: 100 | G32: Romance | H32: 3 | I32: 4 | J32: FALSE | K32: 417 | L32: 87 | M32: France | N32: Credit Card | O32: English | P32: 14 | Q32: 3.4 | R32: FALSE | S32: Active | T32: 3183 | U32: Smart TV | V32: 35-44 | W32: Afternoon | X32: -1 | Y32: STANDARD | Z32: -700 | AA32: Swapped Join Date & Last Login Date
A33: 1282 | B33: Amy | C33: 45636 | D33: 45623 | E33: 15.99 | F33: 432 | G33: Horror | H33: 4 | I33: 3 | J33: TRUE | K33: 666 | L33: 76 | M33: Australia | N33: Cryptocurrency | O33: French | P33: 92 | Q33: 4.6 | R33: FALSE | S33: Active | T33: 4020 | U33: Tablet | V33: 45-54 | W33: Late Night | X33: -13 | Y33: PREMIUM | Z33: -232.61538 | AA33: Swapped Join Date & Last Login Date
... A40: 4680 | B40: Alexandria | C40: 45642 | D40: 45637 | E40: 11.99 | F40: 221 | G40: Romance | H40: 5 | I40: 5 | J40: TRUE | K40: 749 | L40: 66 | M40: USA | N40: Cryptocurrency | O40: German | P40: 37 | Q40: 3.3 | R40: TRUE | S40: Active | T40: 4505 | U40: Smart TV | V40: 35-44 | W40: Afternoon | X40: -5 | Y40: STANDARD | Z40: -309.4 | AA40: Swapped Join Date & Last Login Date
A41: 4115 | B41: Shawna | C41: 45620 | D41: 45620 | E41: 15.99 | F41: 158 | G41: Comedy | H41: 1 | I41: 5 | J41: TRUE | K41: 603 | L41: 72 | M41: India | N41: Credit Card | O41: Hindi | P41: 88 | Q41: 3.3 | R41: FALSE | S41: Active | T41: 3508 | U41: Smart TV | V41: 55+ | W41: Afternoon | X41: =D41-C41 -> 0 | Y41: {=_xlfn.IFS(E41=7.99,"BASIC",E41=11.99,"STANDARD",E41=15.99,"PREMIUM")} -> PREMIUM | Z41: You can see it's mentioned the hours as 158 but the date is incorrect | AA41: Joined Date & Last Date Was Same So Changed It By One Month

Sheet Cleaned Data
A1: User_ID | B1: User_Name | C1: Join_Date | D1: Last_Login | E1: Monthly_Price | F1: Watch_Hours | G1: Favorite_Genre | H1: Active_Devices | I1: Profile_Count | J1: Parental_Controls | K1: Total_Movies_Watched | L1: Total_Series_Watched | M1: Country | N1: Payment_Method | O1: Language_Preference | P1: Recommended_Content_Count | Q1: Average_Rating_Given | R1: Has_Downloaded_Content | S1: Membership_Status | T1: Loyalty_Points | U1: First_Device_Used | V1: Age_Group | W1: Primary_Watch_Time | X1: Tenure Days | Y1: Price Tier | Z1: Watch HR per Week | AA1: Frequency Bucket | AB1: Per Day Watch Hr | AC1: BR/VW
A2: 2518 | B2: Amber | C2: 45061 | D2: 45639 | E2: 7.99 | F2: 49 | G2: Action | H2: 3 | I2: 6 | J2: TRUE | K2: 641 | L2: 117 | M2: USA | N2: PayPal | O2: Hindi | P2: 84 | Q2: 3.3 | R2: FALSE | S2: Active | T2: 2878 | U2: Smartphone | V2: 35-44 | W2: Late Night | X2: =D2-C2 -> 578 | Y2: {=_xlfn.IFS(E2=7.99,"BASIC",E2=11.99,"STANDARD",E2=15.99,"PREMIUM")} -> BASIC | Z2: =F2/(X2/7) -> 0.59342561 | AA2: {=_xlfn.IFS( (F2/(X2/7)) < 5, "Casual", AND((F2/(X2/7)) >= 5, (F2/(X2/7)) < 15), "Regular", (F2/(X2/7)) >= 15, "Power" )} -> Casual | AB2: =(F2/(K2+L2)) -> 0.064643799 | AC2: =IF(F2/(K2+L2) < 0.15," Browsers","Viewers") -> Browsers
A3: 6430 | B3: Patrick | C3: 45019 | D3: 45641 | E3: 7.99 | F3: 161 | G3: Drama | H3: 1 | I3: 2 | J3: TRUE | K3: 192 | L3: 65 | M3: USA | N3: PayPal | O3: German | P3: 69 | Q3: 4 | R3: FALSE | S3: Active | T3: 2291 | U3: Desktop | V3: 25-34 | W3: Evening | X3: =D3-C3 -> 622 | Y3: {=_xlfn.IFS(E3=7.99,"BASIC",E3=11.99,"STANDARD",E3=15.99,"PREMIUM")} -> BASIC | Z3: =F3/(X3/7) -> 1.8118971 | AA3: {=_xlfn.IFS( (F3/(X3/7)) < 5, "Casual", AND((F3/(X3/7)) >= 5, (F3/(X3/7)) < 15), "Regular", (F3/(X3/7)) >= 15, "Power" )} -> Casual | AB3: =(F3/(K3+L3)) -> 0.62645914 | AC3: =IF(F3/(K3+L3) < 0.15," Browsers","Viewers") -> Viewers
A4: 1798 | B4: Robert | C4: 45140 | D4: 45640 | E4: 11.99 | F4: 87 | G4: Action | H4: 2 | I4: 5 | J4: FALSE | K4: 260 | L4: 127 | M4: Canada | N4: Debit Card | O4: Mandarin | P4: 56 | Q4: 3.1 | R4: FALSE | S4: Active | T4: 1692 | U4: Desktop | V4: 35-44 | W4: Late Night | X4: =D4-C4 -> 500 | Y4: {=_xlfn.IFS(E4=7.99,"BASIC",E4=11.99,"STANDARD",E4=15.99,"PREMIUM")} -> STANDARD | Z4: =F4/(X4/7) -> 1.218 | AA4: {=_xlfn.IFS( (F4/(X4/7)) < 5, "Casual", AND((F4/(X4/7)) >= 5, (F4/(X4/7)) < 15), "Regular", (F4/(X4/7)) >= 15, "Power" )} -> Casual | AB4: =(F4/(K4+L4)) -> 0.2248062 | AC4: =IF(F4/(K4+L4) < 0.15," Browsers","Viewers") -> Viewers
A5: 5255 | B5: Cole | C5: 44957 | D5: 45628 | E5: 15.99 | F5: 321 | G5: Sci-Fi | H5: 1 | I5: 5 | J5: FALSE | K5: 61 | L5: 192 | M5: UK | N5: Debit Card | O5: Mandarin | P5: 47 | Q5: 4.6 | R5: FALSE | S5: Active | T5: 952 | U5: Desktop | V5: 25-34 | W5: Evening | X5: =D5-C5 -> 671 | Y5: {=_xlfn.IFS(E5=7.99,"BASIC",E5=11.99,"STANDARD",E5=15.99,"PREMIUM")} -> PREMIUM | Z5: =F5/(X5/7) -> 3.3487332 | AA5: {=_xlfn.IFS( (F5/(X5/7)) < 5, "Casual", AND((F5/(X5/7)) >= 5, (F5/(X5/7)) < 15), "Regular", (F5/(X5/7)) >= 15, "Power" )} -> Casual | AB5: =(F5/(K5+L5)) -> 1.2687747 | AC5: =IF(F5/(K5+L5) < 0.15," Browsers","Viewers") -> Viewers
A6: 2854 | B6: Jamie | C6: 45083 | D6: 45641 | E6: 11.99 | F6: 386 | G6: Documentary | H6: 1 | I6: 4 | J6: TRUE | K6: 230 | L6: 2 | M6: USA | N6: PayPal | O6: Mandarin | P6: 39 | Q6: 3.7 | R6: FALSE | S6: Active | T6: 1823 | U6: Desktop | V6: 25-34 | W6: Late Night | X6: =D6-C6 -> 558 | Y6: {=_xlfn.IFS(E6=7.99,"BASIC",E6=11.99,"STANDARD",E6=15.99,"PREMIUM")} -> STANDARD | Z6: =F6/(X6/7) -> 4.8422939 | AA6: {=_xlfn.IFS( (F6/(X6/7)) < 5, "Casual", AND((F6/(X6/7)) >= 5, (F6/(X6/7)) < 15), "Regular", (F6/(X6/7)) >= 15, "Power" )} -> Casual | AB6: =(F6/(K6+L6)) -> 1.6637931 | AC6: =IF(F6/(K6+L6) < 0.15," Browsers","Viewers") -> Viewers
A7: 6735 | B7: Mary | C7: 45186 | D7: 45615 | E7: 15.99 | F7: 408 | G7: Documentary | H7: 2 | I7: 6 | J7: TRUE | K7: 837 | L7: 105 | M7: India | N7: Credit Card | O7: Spanish | P7: 71 | Q7: 4.3 | R7: TRUE | S7: Active | T7: 33 | U7: Smart TV | V7: 18-24 | W7: Morning | X7: =D7-C7 -> 429 | Y7: {=_xlfn.IFS(E7=7.99,"BASIC",E7=11.99,"STANDARD",E7=15.99,"PREMIUM")} -> PREMIUM | Z7: =F7/(X7/7) -> 6.6573427 | AA7: {=_xlfn.IFS( (F7/(X7/7)) < 5, "Casual", AND((F7/(X7/7)) >= 5, (F7/(X7/7)) < 15), "Regular", (F7/(X7/7)) >= 15, "Power" )} -> Regular | AB7: =(F7/(K7+L7)) -> 0.43312102 | AC7: =IF(F7/(K7+L7) < 0.15," Browsers","Viewers") -> Viewers
A8: 2995 | B8: Theodore | C8: 45529 | D8: 45636 | E8: 7.99 | F8: 475 | G8: Horror | H8: 5 | I8: 4 | J8: TRUE | K8: 510 | L8: 143 | M8: USA | N8: Credit Card | O8: English | P8: 1 | Q8: 4.5 | R8: FALSE | S8: Active | T8: 755 | U8: Laptop | V8: 35-44 | W8: Late Night | X8: =D8-C8 -> 107 | Y8: {=_xlfn.IFS(E8=7.99,"BASIC",E8=11.99,"STANDARD",E8=15.99,"PREMIUM")} -> BASIC | Z8: =F8/(X8/7) -> 31.074766 | AA8: {=_xlfn.IFS( (F8/(X8/7)) < 5, "Casual", AND((F8/(X8/7)) >= 5, (F8/(X8/7)) < 15), "Regular", (F8/(X8/7)) >= 15, "Power" )} -> Power | AB8: =(F8/(K8+L8)) -> 0.72741194 | AC8: =IF(F8/(K8+L8) < 0.15," Browsers","Viewers") -> Viewers
A9: 5120 | B9: Olivia | C9: 45443 | D9: 45640 | E9: 15.99 | F9: 258 | G9: Action | H9: 4 | I9: 1 | J9: TRUE | K9: 907 | L9: 47 | M9: Australia | N9: Debit Card | O9: Hindi | P9: 32 | Q9: 3.7 | R9: TRUE | S9: Active | T9: 2866 | U9: Smartphone | V9: 45-54 | W9: Late Night | X9: =D9-C9 -> 197 | Y9: {=_xlfn.IFS(E9=7.99,"BASIC",E9=11.99,"STANDARD",E9=15.99,"PREMIUM")} -> PREMIUM | Z9: =F9/(X9/7) -> 9.1675127 | AA9: {=_xlfn.IFS( (F9/(X9/7)) < 5, "Casual", AND((F9/(X9/7)) >= 5, (F9/(X9/7)) < 15), "Regular", (F9/(X9/7)) >= 15, "Power" )} -> Regular | AB9: =(F9/(K9+L9)) -> 0.27044025 | AC9: =IF(F9/(K9+L9) < 0.15," Browsers","Viewers") -> Viewers
A10: 6063 | B10: Patricia | C10: 45094 | D10: 45643 | E10: 15.99 | F10: 183 | G10: Comedy | H10: 5 | I10: 2 | J10: TRUE | K10: 676 | L10: 61 | M10: Germany | N10: Cryptocurrency | O10: Mandarin | P10: 26 | Q10: 3.3 | R10: TRUE | S10: Active | T10: 336 | U10: Tablet | V10: 25-34 | W10: Late Night | X10: =D10-C10 -> 549 | Y10: {=_xlfn.IFS(E10=7.99,"BASIC",E10=11.99,"STANDARD",E10=15.99,"PREMIUM")} -> PREMIUM | Z10: =F10/(X10/7) -> 2.3333333 | AA10: {=_xlfn.IFS( (F10/(X10/7)) < 5, "Casual", AND((F10/(X10/7)) >= 5, (F10/(X10/7)) < 15), "Regular", (F10/(X10/7)) >= 15, "Power" )} -> Casual | AB10: =(F10/(K10+L10)) -> 0.24830393 | AC10: =IF(F10/(K10+L10) < 0.15," Browsers","Viewers") -> Viewers
A11: 6896 | B11: Linda | C11: 45262 | D11: 45640 | E11: 7.99 | F11: 164 | G11: Documentary | H11: 5 | I11: 4 | J11: TRUE | K11: 406 | L11: 79 | M11: USA | N11: Credit Card | O11: French | P11: 90 | Q11: 3.2 | R11: FALSE | S11: Active | T11: 3898 | U11: Laptop | V11: 55+ | W11: Late Night | X11: =D11-C11 -> 378 | Y11: {=_xlfn.IFS(E11=7.99,"BASIC",E11=11.99,"STANDARD",E11=15.99,"PREMIUM")} -> BASIC | Z11: =F11/(X11/7) -> 3.037037 | AA11: {=_xlfn.IFS( (F11/(X11/7)) < 5, "Casual", AND((F11/(X11/7)) >= 5, (F11/(X11/7)) < 15), "Regular", (F11/(X11/7)) >= 15, "Power" )} -> Casual | AB11: =(F11/(K11+L11)) -> 0.33814433 | AC11: =IF(F11/(K11+L11) < 0.15," Browsers","Viewers") -> Viewers
A12: 8447 | B12: Nichole | C12: 45013 | D12: 45618 | E12: 11.99 | F12: 411 | G12: Comedy | H12: 5 | I12: 4 | J12: TRUE | K12: 352 | L12: 78 | M12: UK | N12: Credit Card | O12: English | P12: 47 | Q12: 3.7 | R12: FALSE | S12: Active | T12: 650 | U12: Tablet | V12: 55+ | W12: Late Night | X12: =D12-C12 -> 605 | Y12: {=_xlfn.IFS(E12=7.99,"BASIC",E12=11.99,"STANDARD",E12=15.99,"PREMIUM")} -> STANDARD | Z12: =F12/(X12/7) -> 4.7553719 | AA12: {=_xlfn.IFS( (F12/(X12/7)) < 5, "Casual", AND((F12/(X12/7)) >= 5, (F12/(X12/7)) < 15), "Regular", (F12/(X12/7)) >= 15, "Power" )} -> Casual | AB12: =(F12/(K12+L12)) -> 0.95581395 | AC12: =IF(F12/(K12+L12) < 0.15," Browsers","Viewers") -> Viewers
A13: 1433 | B13: Frances | C13: 45353 | D13: 45616 | E13: 15.99 | F13: 160 | G13: Drama | H13: 5 | I13: 6 | J13: TRUE | K13: 391 | L13: 132 | M13: Canada | N13: Debit Card | O13: German | P13: 57 | Q13: 3 | R13: FALSE | S13: Active | T13: 185 | U13: Laptop | V13: 35-44 | W13: Late Night | X13: =D13-C13 -> 263 | Y13: {=_xlfn.IFS(E13=7.99,"BASIC",E13=11.99,"STANDARD",E13=15.99,"PREMIUM")} -> PREMIUM | Z13: =F13/(X13/7) -> 4.2585551 | AA13: {=_xlfn.IFS( (F13/(X13/7)) < 5, "Casual", AND((F13/(X13/7)) >= 5, (F13/(X13/7)) < 15), "Regular", (F13/(X13/7)) >= 15, "Power" )} -> Casual | AB13: =(F13/(K13+L13)) -> 0.30592734 | AC13: =IF(F13/(K13+L13) < 0.15," Browsers","Viewers") -> Viewers
... A32: 4815 | B32: Ariel | C32: 45475 | D32: 45616 | E32: 7.99 | F32: 52 | G32: Documentary | H32: 5 | I32: 5 | J32: FALSE | K32: 467 | L32: 23 | M32: USA | N32: PayPal | O32: Spanish | P32: 97 | Q32: 3.3 | R32: TRUE | S32: Active | T32: 4185 | U32: Desktop | V32: 55+ | W32: Evening | X32: =D32-C32 -> 141 | Y32: {=_xlfn.IFS(E32=7.99,"BASIC",E32=11.99,"STANDARD",E32=15.99,"PREMIUM")} -> BASIC | Z32: =F32/(X32/7) -> 2.5815603 | AA32: {=_xlfn.IFS( (F32/(X32/7)) < 5, "Casual", AND((F32/(X32/7)) >= 5, (F32/(X32/7)) < 15), "Regular", (F32/(X32/7)) >= 15, "Power" )} -> Casual | AB32: =(F32/(K32+L32)) -> 0.10612245 | AC32: =IF(F32/(K32+L32) < 0.15," Browsers","Viewers") -> Browsers
A33: 9597 | B33: Lauren | C33: =_xlfn.XLOOKUP(A33,'Data Anomalies -Pls Read It'!A:A,'Data Anomalies -Pls Read It'!D:D,1,0) -> 45628 | D33: =_xlfn.XLOOKUP(A33,'Data Anomalies -Pls Read It'!A:A,'Data Anomalies -Pls Read It'!C:C,1,0) -> 45632 | E33: 11.99 | F33: 447 | G33: Romance | H33: 5 | I33: 5 | J33: FALSE | K33: 73 | L33: 138 | M33: Germany | N33: Debit Card | O33: Hindi | P33: 84 | Q33: 4.1 | R33: FALSE | S33: Active | T33: 784 | U33: Smartphone | V33: 25-34 | W33: Afternoon | X33: =D33-C33 -> 4 | Y33: {=_xlfn.IFS(E33=7.99,"BASIC",E33=11.99,"STANDARD",E33=15.99,"PREMIUM")} -> STANDARD | Z33: =F33/(X33/7) -> 782.25 | AA33: {=_xlfn.IFS( (F33/(X33/7)) < 5, "Casual", AND((F33/(X33/7)) >= 5, (F33/(X33/7)) < 15), "Regular", (F33/(X33/7)) >= 15, "Power" )} -> Power | AB33: =(F33/(K33+L33)) -> 2.1184834 | AC33: =IF(F33/(K33+L33) < 0.15," Browsers","Viewers") -> Viewers | AD33: Correction
A34: 6566 | B34: Joshua | C34: 45099 | D34: 45643 | E34: 11.99 | F34: 312 | G34: Horror | H34: 5 | I34: 1 | J34: TRUE | K34: 895 | L34: 154 | M34: Germany | N34: Debit Card | O34: Spanish | P34: 85 | Q34: 4.7 | R34: TRUE | S34: Active | T34: 3428 | U34: Laptop | V34: 25-34 | W34: Evening | X34: =D34-C34 -> 544 | Y34: {=_xlfn.IFS(E34=7.99,"BASIC",E34=11.99,"STANDARD",E34=15.99,"PREMIUM")} -> STANDARD | Z34: =F34/(X34/7) -> 4.0147059 | AA34: {=_xlfn.IFS( (F34/(X34/7)) < 5, "Casual", AND((F34/(X34/7)) >= 5, (F34/(X34/7)) < 15), "Regular", (F34/(X34/7)) >= 15, "Power" )} -> Casual | AB34: =(F34/(K34+L34)) -> 0.29742612 | AC34: =IF(F34/(K34+L34) < 0.15," Browsers","Viewers") -> Viewers
A35: 1419 | B35: Megan | C35: 45110 | D35: 45642 | E35: 11.99 | F35: 406 | G35: Sci-Fi | H35: 2 | I35: 6 | J35: FALSE | K35: 983 | L35: 113 | M35: India | N35: Cryptocurrency | O35: German | P35: 78 | Q35: 3.1 | R35: FALSE | S35: Active | T35: 4245 | U35: Smartphone | V35: 25-34 | W35: Evening | X35: =D35-C35 -> 532 | Y35: {=_xlfn.IFS(E35=7.99,"BASIC",E35=11.99,"STANDARD",E35=15.99,"PREMIUM")} -> STANDARD | Z35: =F35/(X35/7) -> 5.3421053 | AA35: {=_xlfn.IFS( (F35/(X35/7)) < 5, "Casual", AND((F35/(X35/7)) >= 5, (F35/(X35/7)) < 15), "Regular", (F35/(X35/7)) >= 15, "Power" )} -> Regular | AB35: =(F35/(K35+L35)) -> 0.37043796 | AC35: =IF(F35/(K35+L35) < 0.15," Browsers","Viewers") -> Viewers
A36: 9470 | B36: Stephanie | C36: 45258 | D36: 45641 | E36: 7.99 | F36: 350 | G36: Horror | H36: 3 | I36: 6 | J36: TRUE | K36: 801 | L36: 156 | M36: France | N36: Credit Card | O36: Mandarin | P36: 66 | Q36: 4.6 | R36: TRUE | S36: Active | T36: 2580 | U36: Smart TV | V36: 18-24 | W36: Late Night | X36: =D36-C36 -> 383 | Y36: {=_xlfn.IFS(E36=7.99,"BASIC",E36=11.99,"STANDARD",E36=15.99,"PREMIUM")} -> BASIC | Z36: =F36/(X36/7) -> 6.3968668 | AA36: {=_xlfn.IFS( (F36/(X36/7)) < 5, "Casual", AND((F36/(X36/7)) >= 5, (F36/(X36/7)) < 15), "Regular", (F36/(X36/7)) >= 15, "Power" )} -> Regular | AB36: =(F36/(K36+L36)) -> 0.36572623 | AC36: =IF(F36/(K36+L36) < 0.15," Browsers","Viewers") -> Viewers
A37: 4989 | B37: Terrence | C37: 45301 | D37: 45636 | E37: 7.99 | F37: 99 | G37: Comedy | H37: 2 | I37: 5 | J37: TRUE | K37: 96 | L37: 114 | M37: USA | N37: PayPal | O37: Hindi | P37: 45 | Q37: 4.3 | R37: FALSE | S37: Active | T37: 2779 | U37: Smart TV | V37: 55+ | W37: Morning | X37: =D37-C37 -> 335 | Y37: {=_xlfn.IFS(E37=7.99,"BASIC",E37=11.99,"STANDARD",E37=15.99,"PREMIUM")} -> BASIC | Z37: =F37/(X37/7) -> 2.0686567 | AA37: {=_xlfn.IFS( (F37/(X37/7)) < 5, "Casual", AND((F37/(X37/7)) >= 5, (F37/(X37/7)) < 15), "Regular", (F37/(X37/7)) >= 15, "Power" )} -> Casual | AB37: =(F37/(K37+L37)) -> 0.47142857 | AC37: =IF(F37/(K37+L37) < 0.15," Browsers","Viewers") -> Viewers
A38: 9389 | B38: Julia | C38: 45568 | D38: 45617 | E38: 15.99 | F38: 53 | G38: Sci-Fi | H38: 1 | I38: 2 | J38: FALSE | K38: 849 | L38: 98 | M38: India | N38: Credit Card | O38: Mandarin | P38: 14 | Q38: 3.1 | R38: FALSE | S38: Active | T38: 2318 | U38: Smartphone | V38: 35-44 | W38: Evening | X38: =D38-C38 -> 49 | Y38: {=_xlfn.IFS(E38=7.99,"BASIC",E38=11.99,"STANDARD",E38=15.99,"PREMIUM")} -> PREMIUM | Z38: =F38/(X38/7) -> 7.5714286 | AA38: {=_xlfn.IFS( (F38/(X38/7)) < 5, "Casual", AND((F38/(X38/7)) >= 5, (F38/(X38/7)) < 15), "Regular", (F38/(X38/7)) >= 15, "Power" )} -> Regular | AB38: =(F38/(K38+L38)) -> 0.055966209 | AC38: =IF(F38/(K38+L38) < 0.15," Browsers","Viewers") -> Browsers
A39: 7728 | B39: Derrick | C39: 45184 | D39: 45639 | E39: 11.99 | F39: 484 | G39: Romance | H39: 3 | I39: 6 | J39: FALSE | K39: 515 | L39: 174 | M39: UK | N39: PayPal | O39: German | P39: 12 | Q39: 4 | R39: TRUE | S39: Active | T39: 827 | U39: Smartphone | V39: 25-34 | W39: Morning | X39: =D39-C39 -> 455 | Y39: {=_xlfn.IFS(E39=7.99,"BASIC",E39=11.99,"STANDARD",E39=15.99,"PREMIUM")} -> STANDARD | Z39: =F39/(X39/7) -> 7.4461538 | AA39: {=_xlfn.IFS( (F39/(X39/7)) < 5, "Casual", AND((F39/(X39/7)) >= 5, (F39/(X39/7)) < 15), "Regular", (F39/(X39/7)) >= 15, "Power" )} -> Regular | AB39: =(F39/(K39+L39)) -> 0.70246734 | AC39: =IF(F39/(K39+L39) < 0.15," Browsers","Viewers") -> Viewers
A40: 7943 | B40: Nathan | C40: 45566 | D40: 45627 | E40: 15.99 | F40: 211 | G40: Documentary | H40: 2 | I40: 6 | J40: TRUE | K40: 657 | L40: 137 | M40: Australia | N40: Credit Card | O40: Hindi | P40: 26 | Q40: 4 | R40: TRUE | S40: Active | T40: 2670 | U40: Desktop | V40: 18-24 | W40: Late Night | X40: =D40-C40 -> 61 | Y40: {=_xlfn.IFS(E40=7.99,"BASIC",E40=11.99,"STANDARD",E40=15.99,"PREMIUM")} -> PREMIUM | Z40: =F40/(X40/7) -> 24.213115 | AA40: {=_xlfn.IFS( (F40/(X40/7)) < 5, "Casual", AND((F40/(X40/7)) >= 5, (F40/(X40/7)) < 15), "Regular", (F40/(X40/7)) >= 15, "Power" )} -> Power | AB40: =(F40/(K40+L40)) -> 0.26574307 | AC40: =IF(F40/(K40+L40) < 0.15," Browsers","Viewers") -> Viewers
A41: 2490 | B41: Matthew | C41: 45156 | D41: 45615 | E41: 11.99 | F41: 248 | G41: Sci-Fi | H41: 4 | I41: 1 | J41: TRUE | K41: 426 | L41: 21 | M41: India | N41: Debit Card | O41: Spanish | P41: 99 | Q41: 4.8 | R41: FALSE | S41: Active | T41: 2409 | U41: Smartphone | V41: 35-44 | W41: Late Night | X41: =D41-C41 -> 459 | Y41: {=_xlfn.IFS(E41=7.99,"BASIC",E41=11.99,"STANDARD",E41=15.99,"PREMIUM")} -> STANDARD | Z41: =F41/(X41/7) -> 3.7821351 | AA41: {=_xlfn.IFS( (F41/(X41/7)) < 5, "Casual", AND((F41/(X41/7)) >= 5, (F41/(X41/7)) < 15), "Regular", (F41/(X41/7)) >= 15, "Power" )} -> Casual | AB41: =(F41/(K41+L41)) -> 0.55480984 | AC41: =IF(F41/(K41+L41) < 0.15," Browsers","Viewers") -> Viewers
A42: 5042 | B42: Ashley | C42: 45338 | D42: 45619 | E42: 15.99 | F42: 197 | G42: Romance | H42: 4 | I42: 2 | J42: FALSE | K42: 309 | L42: 178 | M42: Australia | N42: Cryptocurrency | O42: Mandarin | P42: 7 | Q42: 4.3 | R42: FALSE | S42: Active | T42: 1577 | U42: Smart TV | V42: 35-44 | W42: Evening | X42: =D42-C42 -> 281 | Y42: {=_xlfn.IFS(E42=7.99,"BASIC",E42=11.99,"STANDARD",E42=15.99,"PREMIUM")} -> PREMIUM | Z42: =F42/(X42/7) -> 4.9074733 | AA42: {=_xlfn.IFS( (F42/(X42/7)) < 5, "Casual", AND((F42/(X42/7)) >= 5, (F42/(X42/7)) < 15), "Regular", (F42/(X42/7)) >= 15, "Power" )} -> Casual | AB42: =(F42/(K42+L42)) -> 0.40451745 | AC42: =IF(F42/(K42+L42) < 0.15," Browsers","Viewers") -> Viewers
A43: 3620 | B43: Kerri | C43: 45511 | D43: 45633 | E43: 15.99 | F43: 253 | G43: Comedy | H43: 5 | I43: 5 | J43: TRUE | K43: 141 | L43: 199 | M43: USA | N43: Debit Card | O43: French | P43: 72 | Q43: 3.1 | R43: FALSE | S43: Active | T43: 4072 | U43: Laptop | V43: 45-54 | W43: Afternoon | X43: =D43-C43 -> 122 | Y43: {=_xlfn.IFS(E43=7.99,"BASIC",E43=11.99,"STANDARD",E43=15.99,"PREMIUM")} -> PREMIUM | Z43: =F43/(X43/7) -> 14.516393 | AA43: {=_xlfn.IFS( (F43/(X43/7)) < 5, "Casual", AND((F43/(X43/7)) >= 5, (F43/(X43/7)) < 15), "Regular", (F43/(X43/7)) >= 15, "Power" )} -> Regular | AB43: =(F43/(K43+L43)) -> 0.74411765 | AC43: =IF(F43/(K43+L43) < 0.15," Browsers","Viewers") -> Viewers
A44: 8976 | B44: Jessica | C44: 45552 | D44: 45638 | E44: 7.99 | F44: 352 | G44: Romance | H44: 4 | I44: 3 | J44: TRUE | K44: 112 | L44: 106 | M44: France | N44: Credit Card | O44: French | P44: 33 | Q44: 4.6 | R44: TRUE | S44: Active | T44: 3432 | U44: Tablet | V44: 45-54 | W44: Afternoon | X44: =D44-C44 -> 86 | Y44: {=_xlfn.IFS(E44=7.99,"BASIC",E44=11.99,"STANDARD",E44=15.99,"PREMIUM")} -> BASIC | Z44: =F44/(X44/7) -> 28.651163 | AA44: {=_xlfn.IFS( (F44/(X44/7)) < 5, "Casual", AND((F44/(X44/7)) >= 5, (F44/(X44/7)) < 15), "Regular", (F44/(X44/7)) >= 15, "Power" )} -> Power | AB44: =(F44/(K44+L44)) -> 1.6146789 | AC44: =IF(F44/(K44+L44) < 0.15," Browsers","Viewers") -> Viewers
A45: 1570 | B45: Matthew | C45: 45125 | D45: 45618 | E45: 11.99 | F45: 97 | G45: Romance | H45: 1 | I45: 2 | J45: FALSE | K45: 836 | L45: 122 | M45: UK | N45: Debit Card | O45: Spanish | P45: 65 | Q45: 4.3 | R45: TRUE | S45: Active | T45: 4511 | U45: Smartphone | V45: 18-24 | W45: Morning | X45: =D45-C45 -> 493 | Y45: {=_xlfn.IFS(E45=7.99,"BASIC",E45=11.99,"STANDARD",E45=15.99,"PREMIUM")} -> STANDARD | Z45: =F45/(X45/7) -> 1.3772819 | AA45: {=_xlfn.IFS( (F45/(X45/7)) < 5, "Casual", AND((F45/(X45/7)) >= 5, (F45/(X45/7)) < 15), "Regular", (F45/(X45/7)) >= 15, "Power" )} -> Casual | AB45: =(F45/(K45+L45)) -> 0.10125261 | AC45: =IF(F45/(K45+L45) < 0.15," Browsers","Viewers") -> Browsers
... A121: 3354 | B121: Lisa | C121: 45200 | D121: 45618 | E121: 11.99 | F121: 342 | G121: Comedy | H121: 2 | I121: 2 | J121: FALSE | K121: 503 | L121: 6 | M121: France | N121: PayPal | O121: French | P121: 23 | Q121: 3.2 | R121: TRUE | S121: Active | T121: 3496 | U121: Laptop | V121: 45-54 | W121: Afternoon | X121: =D121-C121 -> 418 | Y121: {=_xlfn.IFS(E121=7.99,"BASIC",E121=11.99,"STANDARD",E121=15.99,"PREMIUM")} -> STANDARD | Z121: =F121/(X121/7) -> 5.7272727 | AA121: {=_xlfn.IFS( (F121/(X121/7)) < 5, "Casual", AND((F121/(X121/7)) >= 5, (F121/(X121/7)) < 15), "Regular", (F121/(X121/7)) >= 15, "Power" )} -> Regular | AB121: =(F121/(K121+L121)) -> 0.6719057 | AC121: =IF(F121/(K121+L121) < 0.15," Browsers","Viewers") -> Viewers
A122: 4668 | B122: Carly | C122: =_xlfn.XLOOKUP(A122,'Data Anomalies -Pls Read It'!A:A,'Data Anomalies -Pls Read It'!D:D,1,0) -> 45635 | D122: =_xlfn.XLOOKUP(A122,'Data Anomalies -Pls Read It'!A:A,'Data Anomalies -Pls Read It'!C:C,1,0) -> 45643 | E122: 11.99 | F122: 396 | G122: Sci-Fi | H122: 5 | I122: 5 | J122: TRUE | K122: 549 | L122: 35 | M122: Canada | N122: PayPal | O122: German | P122: 66 | Q122: 3.6 | R122: TRUE | S122: Active | T122: 4293 | U122: Laptop | V122: 55+ | W122: Morning | X122: =D122-C122 -> 8 | Y122: {=_xlfn.IFS(E122=7.99,"BASIC",E122=11.99,"STANDARD",E122=15.99,"PREMIUM")} -> STANDARD | Z122: =F122/(X122/7) -> 346.5 | AA122: {=_xlfn.IFS( (F122/(X122/7)) < 5, "Casual", AND((F122/(X122/7)) >= 5, (F122/(X122/7)) < 15), "Regular", (F122/(X122/7)) >= 15, "Power" )} -> Power | AB122: =(F122/(K122+L122)) -> 0.67808219 | AC122: =IF(F122/(K122+L122) < 0.15," Browsers","Viewers") -> Viewers | AD122: Correction
A123: 6684 | B123: Dennis | C123: 45552 | D123: 45637 | E123: 11.99 | F123: 491 | G123: Romance | H123: 1 | I123: 6 | J123: TRUE | K123: 434 | L123: 182 | M123: Germany | N123: Cryptocurrency | O123: Spanish | P123: 24 | Q123: 4.1 | R123: FALSE | S123: Active | T123: 1357 | U123: Tablet | V123: 45-54 | W123: Late Night | X123: =D123-C123 -> 85 | Y123: {=_xlfn.IFS(E123=7.99,"BASIC",E123=11.99,"STANDARD",E123=15.99,"PREMIUM")} -> STANDARD | Z123: =F123/(X123/7) -> 40.435294 | AA123: {=_xlfn.IFS( (F123/(X123/7)) < 5, "Casual", AND((F123/(X123/7)) >= 5, (F123/(X123/7)) < 15), "Regular", (F123/(X123/7)) >= 15, "Power" )} -> Power | AB123: =(F123/(K123+L123)) -> 0.79707792 | AC123: =IF(F123/(K123+L123) < 0.15," Browsers","Viewers") -> Viewers
A124: 8058 | B124: Alexandra | C124: 45018 | D124: 45640 | E124: 15.99 | F124: 239 | G124: Sci-Fi | H124: 4 | I124: 6 | J124: FALSE | K124: 832 | L124: 134 | M124: Australia | N124: Cryptocurrency | O124: Spanish | P124: 99 | Q124: 4.6 | R124: TRUE | S124: Active | T124: 3596 | U124: Desktop | V124: 18-24 | W124: Morning | X124: =D124-C124 -> 622 | Y124: {=_xlfn.IFS(E124=7.99,"BASIC",E124=11.99,"STANDARD",E124=15.99,"PREMIUM")} -> PREMIUM | Z124: =F124/(X124/7) -> 2.6897106 | AA124: {=_xlfn.IFS( (F124/(X124/7)) < 5, "Casual", AND((F124/(X124/7)) >= 5, (F124/(X124/7)) < 15), "Regular", (F124/(X124/7)) >= 15, "Power" )} -> Casual | AB124: =(F124/(K124+L124)) -> 0.24741201 | AC124: =IF(F124/(K124+L124) < 0.15," Browsers","Viewers") -> Viewers
A125: 3035 | B125: Michael | C125: 45042 | D125: 45620 | E125: 15.99 | F125: 106 | G125: Romance | H125: 3 | I125: 3 | J125: TRUE | K125: 377 | L125: 31 | M125: Germany | N125: Credit Card | O125: English | P125: 85 | Q125: 3.5 | R125: TRUE | S125: Active | T125: 613 | U125: Desktop | V125: 55+ | W125: Late Night | X125: =D125-C125 -> 578 | Y125: {=_xlfn.IFS(E125=7.99,"BASIC",E125=11.99,"STANDARD",E125=15.99,"PREMIUM")} -> PREMIUM | Z125: =F125/(X125/7) -> 1.283737 | AA125: {=_xlfn.IFS( (F125/(X125/7)) < 5, "Casual", AND((F125/(X125/7)) >= 5, (F125/(X125/7)) < 15), "Regular", (F125/(X125/7)) >= 15, "Power" )} -> Casual | AB125: =(F125/(K125+L125)) -> 0.25980392 | AC125: =IF(F125/(K125+L125) < 0.15," Browsers","Viewers") -> Viewers
A126: 2146 | B126: Ryan | C126: 45484 | D126: 45618 | E126: 11.99 | F126: 388 | G126: Horror | H126: 5 | I126: 4 | J126: TRUE | K126: 380 | L126: 125 | M126: Australia | N126: PayPal | O126: German | P126: 14 | Q126: 3.2 | R126: FALSE | S126: Active | T126: 2381 | U126: Tablet | V126: 25-34 | W126: Afternoon | X126: =D126-C126 -> 134 | Y126: {=_xlfn.IFS(E126=7.99,"BASIC",E126=11.99,"STANDARD",E126=15.99,"PREMIUM")} -> STANDARD | Z126: =F126/(X126/7) -> 20.268657 | AA126: {=_xlfn.IFS( (F126/(X126/7)) < 5, "Casual", AND((F126/(X126/7)) >= 5, (F126/(X126/7)) < 15), "Regular", (F126/(X126/7)) >= 15, "Power" )} -> Power | AB126: =(F126/(K126+L126)) -> 0.76831683 | AC126: =IF(F126/(K126+L126) < 0.15," Browsers","Viewers") -> Viewers
A127: 5761 | B127: Tony | C127: 45311 | D127: 45634 | E127: 15.99 | F127: 452 | G127: Drama | H127: 2 | I127: 5 | J127: FALSE | K127: 315 | L127: 118 | M127: India | N127: Cryptocurrency | O127: Spanish | P127: 28 | Q127: 3 | R127: TRUE | S127: Active | T127: 2159 | U127: Desktop | V127: 45-54 | W127: Morning | X127: =D127-C127 -> 323 | Y127: {=_xlfn.IFS(E127=7.99,"BASIC",E127=11.99,"STANDARD",E127=15.99,"PREMIUM")} -> PREMIUM | Z127: =F127/(X127/7) -> 9.7956656 | AA127: {=_xlfn.IFS( (F127/(X127/7)) < 5, "Casual", AND((F127/(X127/7)) >= 5, (F127/(X127/7)) < 15), "Regular", (F127/(X127/7)) >= 15, "Power" )} -> Regular | AB127: =(F127/(K127+L127)) -> 1.0438799 | AC127: =IF(F127/(K127+L127) < 0.15," Browsers","Viewers") -> Viewers
A128: 5256 | B128: Daniel | C128: 45614 | D128: 45628 | E128: 15.99 | F128: 368 | G128: Sci-Fi | H128: 4 | I128: 4 | J128: TRUE | K128: 968 | L128: 24 | M128: Australia | N128: Debit Card | O128: Mandarin | P128: 30 | Q128: 3 | R128: TRUE | S128: Active | T128: 119 | U128: Tablet | V128: 55+ | W128: Late Night | X128: =D128-C128 -> 14 | Y128: {=_xlfn.IFS(E128=7.99,"BASIC",E128=11.99,"STANDARD",E128=15.99,"PREMIUM")} -> PREMIUM | Z128: =F128/(X128/7) -> 184 | AA128: {=_xlfn.IFS( (F128/(X128/7)) < 5, "Casual", AND((F128/(X128/7)) >= 5, (F128/(X128/7)) < 15), "Regular", (F128/(X128/7)) >= 15, "Power" )} -> Power | AB128: =(F128/(K128+L128)) -> 0.37096774 | AC128: =IF(F128/(K128+L128) < 0.15," Browsers","Viewers") -> Viewers
A129: 5995 | B129: Melissa | C129: 45094 | D129: 45623 | E129: 15.99 | F129: 325 | G129: Action | H129: 2 | I129: 5 | J129: TRUE | K129: 757 | L129: 35 | M129: UK | N129: Credit Card | O129: Mandarin | P129: 81 | Q129: 4.6 | R129: FALSE | S129: Active | T129: 2798 | U129: Smartphone | V129: 25-34 | W129: Late Night | X129: =D129-C129 -> 529 | Y129: {=_xlfn.IFS(E129=7.99,"BASIC",E129=11.99,"STANDARD",E129=15.99,"PREMIUM")} -> PREMIUM | Z129: =F129/(X129/7) -> 4.3005671 | AA129: {=_xlfn.IFS( (F129/(X129/7)) < 5, "Casual", AND((F129/(X129/7)) >= 5, (F129/(X129/7)) < 15), "Regular", (F129/(X129/7)) >= 15, "Power" )} -> Casual | AB129: =(F129/(K129+L129)) -> 0.41035354 | AC129: =IF(F129/(K129+L129) < 0.15," Browsers","Viewers") -> Viewers
A130: 4155 | B130: Jacob | C130: 44992 | D130: 45632 | E130: 11.99 | F130: 42 | G130: Sci-Fi | H130: 4 | I130: 2 | J130: FALSE | K130: 560 | L130: 98 | M130: France | N130: Debit Card | O130: Mandarin | P130: 90 | Q130: 3.8 | R130: FALSE | S130: Active | T130: 496 | U130: Laptop | V130: 18-24 | W130: Afternoon | X130: =D130-C130 -> 640 | Y130: {=_xlfn.IFS(E130=7.99,"BASIC",E130=11.99,"STANDARD",E130=15.99,"PREMIUM")} -> STANDARD | Z130: =F130/(X130/7) -> 0.459375 | AA130: {=_xlfn.IFS( (F130/(X130/7)) < 5, "Casual", AND((F130/(X130/7)) >= 5, (F130/(X130/7)) < 15), "Regular", (F130/(X130/7)) >= 15, "Power" )} -> Casual | AB130: =(F130/(K130+L130)) -> 0.063829787 | AC130: =IF(F130/(K130+L130) < 0.15," Browsers","Viewers") -> Browsers
A131: 1851 | B131: Jennifer | C131: 45202 | D131: 45637 | E131: 11.99 | F131: 344 | G131: Horror | H131: 3 | I131: 1 | J131: FALSE | K131: 456 | L131: 196 | M131: France | N131: Credit Card | O131: Mandarin | P131: 83 | Q131: 5 | R131: FALSE | S131: Active | T131: 3599 | U131: Desktop | V131: 45-54 | W131: Evening | X131: =D131-C131 -> 435 | Y131: {=_xlfn.IFS(E131=7.99,"BASIC",E131=11.99,"STANDARD",E131=15.99,"PREMIUM")} -> STANDARD | Z131: =F131/(X131/7) -> 5.5356322 | AA131: {=_xlfn.IFS( (F131/(X131/7)) < 5, "Casual", AND((F131/(X131/7)) >= 5, (F131/(X131/7)) < 15), "Regular", (F131/(X131/7)) >= 15, "Power" )} -> Regular | AB131: =(F131/(K131+L131)) -> 0.52760736 | AC131: =IF(F131/(K131+L131) < 0.15," Browsers","Viewers") -> Viewers
A132: 8068 | B132: Carolyn | C132: =_xlfn.XLOOKUP(A132,'Data Anomalies -Pls Read It'!A:A,'Data Anomalies -Pls Read It'!D:D,1,0) -> 45619 | D132: =_xlfn.XLOOKUP(A132,'Data Anomalies -Pls Read It'!A:A,'Data Anomalies -Pls Read It'!C:C,1,0) -> 45640 | E132: 15.99 | F132: 77 | G132: Drama | H132: 5 | I132: 3 | J132: FALSE | K132: 780 | L132: 138 | M132: India | N132: Cryptocurrency | O132: French | P132: 66 | Q132: 3.4 | R132: FALSE | S132: Active | T132: 1752 | U132: Tablet | V132: 18-24 | W132: Afternoon | X132: =D132-C132 -> 21 | Y132: {=_xlfn.IFS(E132=7.99,"BASIC",E132=11.99,"STANDARD",E132=15.99,"PREMIUM")} -> PREMIUM | Z132: =F132/(X132/7) -> 25.666667 | AA132: {=_xlfn.IFS( (F132/(X132/7)) < 5, "Casual", AND((F132/(X132/7)) >= 5, (F132/(X132/7)) < 15), "Regular", (F132/(X132/7)) >= 15, "Power" )} -> Power | AB132: =(F132/(K132+L132)) -> 0.083877996 | AC132: =IF(F132/(K132+L132) < 0.15," Browsers","Viewers") -> Browsers | AD132: Correction
A133: 8425 | B133: Patrick | C133: 45610 | D133: 45624 | E133: 7.99 | F133: 237 | G133: Comedy | H133: 5 | I133: 3 | J133: TRUE | K133: 168 | L133: 18 | M133: Australia | N133: Cryptocurrency | O133: Mandarin | P133: 32 | Q133: 3.5 | R133: TRUE | S133: Active | T133: 3633 | U133: Laptop | V133: 25-34 | W133: Evening | X133: =D133-C133 -> 14 | Y133: {=_xlfn.IFS(E133=7.99,"BASIC",E133=11.99,"STANDARD",E133=15.99,"PREMIUM")} -> BASIC | Z133: =F133/(X133/7) -> 118.5 | AA133: {=_xlfn.IFS( (F133/(X133/7)) < 5, "Casual", AND((F133/(X133/7)) >= 5, (F133/(X133/7)) < 15), "Regular", (F133/(X133/7)) >= 15, "Power" )} -> Power | AB133: =(F133/(K133+L133)) -> 1.2741935 | AC133: =IF(F133/(K133+L133) < 0.15," Browsers","Viewers") -> Viewers
...

Sheet Pivot Table
C1: 1. Subscription & Revenue Analysis | L1: 2. User Engagement Metrics: | R1: 3. Demographic & Behavioral Insights: | AB1: 4. Retention & Loyalty: | AJ1: 5. Payment Preferences & Regional Trends
C2: ○ Monthly revenue based on different subscription plans. | G2: ○ Distribution of users across different price tiers. | L2: ○ Average watch hours per user & ○ Total movies vs. series watched per user. | N2: ○ Impact of recommended content on engagement. | R2: ○ Preferred genres by age group. | U2: ○ Device usage trends. | W2: ○ Peak watch time trends (Morning, Evening, Late Night). | AB2: ○ Membership status (Active vs. Inactive). & ○ Loyalty points distribution. | AE2: ○ Frequency of logins and content downloads. | AJ2: ○ Preferred payment methods by region. ○ Subscription trends by country. | AM2: ○ Language preferences and their correlation with engagement.
D4: Subscription Tier | E4: User Count | F4: Subscription Amount | H4: Subscription Tier | I4: Price | L4: Age Group | M4: No. of Movies Watched | N4: No. of Series Watched | R4: Count of User_ID | S4: Column Labels | AJ4: Subscription Tier | AK4: (All)
D5: BASIC | E5: 323 | F5: 2580.77 | H5: BASIC | I5: 7.99 | L5: 18-24 | M5: 522.77778 | N5: 109.94444 | R5: Age Group | S5: Action | T5: Comedy | U5: Documentary | V5: Drama | W5: Horror | X5: Romance | Y5: Sci-Fi | AB5: Status | AC5: Count of User_ID | AE5: Has Downloaded | AF5: Count of User_ID | AG5: Average of Watch_Hours
D6: STANDARD | E6: 345 | F6: 4136.55 | H6: STANDARD | I6: 11.99 | L6: 25-34 | M6: 502.71 | N6: 93.155 | R6: 18-24 | S6: 26 | T6: 23 | U6: 36 | V6: 25 | W6: 23 | X6: 24 | Y6: 23 | AB6: Active | AC6: 1000 | AE6: Downloaded | AF6: 499 | AG6: 257.42485 | AJ6: Count of User_ID | AK6: Column Labels
D7: PREMIUM | E7: 332 | F7: 5308.68 | H7: PREMIUM | I7: 15.99 | L7: 35-44 | M7: 532.03865 | N7: 98.801932 | R7: 25-34 | S7: 33 | T7: 29 | U7: 21 | V7: 31 | W7: 36 | X7: 27 | Y7: 23 | AB7: Grand Total | AC7: 1000 | AE7: Not Downloaded | AF7: 501 | AG7: 251.61876 | AJ7: Country Name | AK7: Credit Card | AL7: Cryptocurrency | AM7: Debit Card | AN7: PayPal
D8: Grand Total | E8: 1000 | F8: 12026 | L8: 45-54 | M8: 500.98558 | N8: 105.87981 | R8: 35-44 | S8: 32 | T8: 29 | U8: 22 | V8: 27 | W8: 34 | X8: 32 | Y8: 31 | AE8: Grand Total | AF8: 1000 | AG8: 254.516 | AJ8: Australia | AK8: 22 | AL8: 44 | AM8: 38 | AN8: 36
L9: 55+ | M9: 521.55122 | N9: 91.95122 | R9: 45-54 | S9: 34 | T9: 26 | U9: 22 | V9: 31 | W9: 32 | X9: 36 | Y9: 27 | AJ9: Canada | AK9: 34 | AL9: 27 | AM9: 36 | AN9: 42
L10: Grand Total | M10: 515.897 | N10: 99.746 | R10: 55+ | S10: 25 | T10: 39 | U10: 29 | V10: 28 | W10: 32 | X10: 27 | Y10: 25 | AB10: Loyalty Points | AC10: Count of User_ID | AJ10: France | AK10: 39 | AL10: 41 | AM10: 31 | AN10: 40
D11: Susbcription Amount | E11: Column Labels | AB11: 0-1000 | AC11: 207 | AE11: Count of User_ID | AF11: Column Labels | AJ11: Germany | AK11: 31 | AL11: 35 | AM11: 43 | AN11: 37
D12: Year & Month | E12: BASIC | F12: STANDARD | G12: PREMIUM | AB12: 1001-2000 | AC12: 215 | AE12: Avg Hrs/Wk | AF12: Not Downloaded | AG12: Downloaded | AJ12: India | AK12: 25 | AL12: 29 | AM12: 39 | AN12: 23
D13: 2022 | E13: 31.96 | F13: 95.92 | G13: 95.94 | L13: Age Group | M13: Watch Hours | R13: Device Name | S13: Users Count | T13: Count of User_ID2 | AB13: 2001-3000 | AC13: 196 | AE13: Casual (0-5 Hours) | AF13: 258 | AG13: 221 | AJ13: UK | AK13: 33 | AL13: 38 | AM13: 31 | AN13: 48
D14: Dec | E14: 31.96 | F14: 95.92 | G14: 95.94 | L14: 18-24 | M14: 237.06111 | R14: Smartphone | S14: 209 | T14: 0.209 | AB14: 3001-4000 | AC14: 191 | AE14: Power (15+ Hours) | AF14: 80 | AG14: 99 | AJ14: USA | AK14: 44 | AL14: 40 | AM14: 31 | AN14: 43
D15: 2023 | E15: 1382.27 | F15: 1978.35 | G15: 2766.27 | L15: 25-34 | M15: 268.52 | R15: Tablet | S15: 215 | T15: 0.215 | AB15: 4001-5000 | AC15: 191 | AE15: Regular (6-15 Hours) | AF15: 163 | AG15: 179 | AJ15: Grand Total | AK15: 228 | AL15: 254 | AM15: 249 | AN15: 269
D16: Jan | E16: 87.89 | F16: 119.9 | G16: 367.77 | L16: 35-44 | M16: 244.95652 | R16: Laptop | S16: 178 | T16: 0.178 | AB16: Grand Total | AC16: 1000 | AE16: Grand Total | AF16: 501 | AG16: 499
D17: Feb | E17: 95.88 | F17: 275.77 | G17: 175.89 | L17: 45-54 | M17: 255.66346 | R17: Desktop | S17: 189 | T17: 0.189
D18: Mar | E18: 127.84 | F18: 131.89 | G18: 175.89 | L18: 55+ | M18: 264.66829 | R18: Smart TV | S18: 209 | T18: 0.209 | AE18: Avg Hrs/Wk | AJ18: Count of User_ID | AK18: Column Labels
D19: Apr | E19: 175.78 | F19: 179.85 | G19: 143.91 | L19: Grand Total | M19: 254.516 | R19: Grand Total | S19: 1000 | T19: 1 | AE19: Weekly Viewing Frequency (Average Watch Hours normalized by Tenure). | AJ19: Country Name | AK19: BASIC | AL19: STANDARD | AM19: PREMIUM
D20: May | E20: 135.83 | F20: 203.83 | G20: 175.89 | AJ20: Australia | AK20: 39 | AL20: 50 | AM20: 51
D21: Jun | E21: 135.83 | F21: 143.88 | G21: 239.85 | L21: RC | AG21: Total Watch Hours | AJ21: Canada | AK21: 46 | AL21: 44 | AM21: 49
D22: Jul | E22: 87.89 | F22: 191.84 | G22: 143.91 | L22: Recommended Content | R22: Primary Watch Time | S22: Users Count | T22: Average of Watch_Hours | AE22: Avg Hrs/Wk | AF22: = | AG22: ------------------------------ | AJ22: France | AK22: 54 | AL22: 50 | AM22: 47
D23: Aug | E23: 87.89 | F23: 119.9 | G23: 175.89 | R23: Morning | S23: 222 | T23: 272.32883 | AG23: (Tenure Days)/7 | AJ23: Germany | AK23: 49 | AL23: 51 | AM23: 46
D24: Sep | E24: 111.86 | F24: 131.89 | G24: 351.78 | L24: RC Count | M24: Avg Watch Hours | R24: Afternoon | S24: 251 | T24: 247.07968 | AJ24: India | AK24: 34 | AL24: 45 | AM24: 37
D25: Oct | E25: 119.85 | F25: 155.87 | G25: 191.88 | L25: 0-20 | M25: 260.28643 | R25: Evening | S25: 256 | T25: 255.39453 | AJ25: UK | AK25: 48 | AL25: 52 | AM25: 50
D26: Nov | E26: 79.9 | F26: 143.88 | G26: 303.81 | L26: 21-40 | M26: 254.64773 | R26: Late Night | S26: 271 | T26: 245.98155 | AJ26: USA | AK26: 53 | AL26: 53 | AM26: 52
D27: Dec | E27: 135.83 | F27: 179.85 | G27: 319.8 | L27: 41-60 | M27: 247.54762 | R27: Grand Total | S27: 1000 | T27: 254.516 | AJ27: Grand Total | AK27: 323 | AL27: 345 | AM27: 332
D28: 2024 | E28: 1166.54 | F28: 2062.28 | G28: 2446.47 | L28: 61-80 | M28: 267.155
D29: Jan | E29: 103.87 | F29: 191.84 | G29: 191.88 | L29: 81-100 | M29: 244.11628
D30: Feb | E30: 103.87 | F30: 155.87 | G30: 255.84 | L30: Grand Total | M30: 254.516 | AJ30: Country Name | AK30: Users Count | AL30: Avg Watch Hours
D31: Mar | E31: 79.9 | F31: 167.86 | G31: 175.89 | AJ31: English | AK31: 168 | AL31: 248.38095
D32: Apr | E32: 95.88 | F32: 191.84 | G32: 191.88 | AJ32: French | AK32: 171 | AL32: 273.46199
D33: May | E33: 111.86 | F33: 167.86 | G33: 255.84 | AJ33: German | AK33: 167 | AL33: 244.79641
D34: Jun | E34: 95.88 | F34: 203.83 | G34: 303.81 | AJ34: Hindi | AK34: 162 | AL34: 253.35802
D35: Jul | E35: 79.9 | F35: 215.82 | G35: 191.88 | AJ35: Mandarin | AK35: 179 | AL35: 243.3352
D36: Aug | E36: 63.92 | F36: 179.85 | G36: 159.9 | AJ36: Spanish | AK36: 153 | AL36: 264.99346
D37: Sep | E37: 143.82 | F37: 179.85 | G37: 207.87 | AJ37: Grand Total | AK37: 1000 | AL37: 254.516
D38: Oct | E38: 159.8 | F38: 179.85 | G38: 175.89
D39: Nov | E39: 95.88 | F39: 107.91 | G39: 255.84
D40: Dec | E40: 31.96 | F40: 119.9 | G40: 79.95
D41: Grand Total | E41: 2580.77 | F41: 4136.55 | G41: 5308.68

Sheet Dashboard
B9: 1. Subscription & Revenue Analysis
B51: 2. User Engagement Metrics:
B87: 3. Demographic & Behavioral Insights:
B88: ='Pivot Table'!R5 -> Age Group | C88: ='Pivot Table'!S5 -> Action | D88: ='Pivot Table'!T5 -> Comedy | E88: ='Pivot Table'!U5 -> Documentary | F88: ='Pivot Table'!V5 -> Drama | G88: ='Pivot Table'!W5 -> Horror | H88: ='Pivot Table'!X5 -> Romance | I88: ='Pivot Table'!Y5 -> Sci-Fi
B89: ='Pivot Table'!R6 -> 18-24 | C89: ='Pivot Table'!S6 -> 26 | D89: ='Pivot Table'!T6 -> 23 | E89: ='Pivot Table'!U6 -> 36 | F89: ='Pivot Table'!V6 -> 25 | G89: ='Pivot Table'!W6 -> 23 | H89: ='Pivot Table'!X6 -> 24 | I89: ='Pivot Table'!Y6 -> 23
B90: ='Pivot Table'!R7 -> 25-34 | C90: ='Pivot Table'!S7 -> 33 | D90: ='Pivot Table'!T7 -> 29 | E90: ='Pivot Table'!U7 -> 21 | F90: ='Pivot Table'!V7 -> 31 | G90: ='Pivot Table'!W7 -> 36 | H90: ='Pivot Table'!X7 -> 27 | I90: ='Pivot Table'!Y7 -> 23
B91: ='Pivot Table'!R8 -> 35-44 | C91: ='Pivot Table'!S8 -> 32 | D91: ='Pivot Table'!T8 -> 29 | E91: ='Pivot Table'!U8 -> 22 | F91: ='Pivot Table'!V8 -> 27 | G91: ='Pivot Table'!W8 -> 34 | H91: ='Pivot Table'!X8 -> 32 | I91: ='Pivot Table'!Y8 -> 31
B92: ='Pivot Table'!R9 -> 45-54 | C92: ='Pivot Table'!S9 -> 34 | D92: ='Pivot Table'!T9 -> 26 | E92: ='Pivot Table'!U9 -> 22 | F92: ='Pivot Table'!V9 -> 31 | G92: ='Pivot Table'!W9 -> 32 | H92: ='Pivot Table'!X9 -> 36 | I92: ='Pivot Table'!Y9 -> 27
B93: ='Pivot Table'!R10 -> 55+ | C93: ='Pivot Table'!S10 -> 25 | D93: ='Pivot Table'!T10 -> 39 | E93: ='Pivot Table'!U10 -> 29 | F93: ='Pivot Table'!V10 -> 28 | G93: ='Pivot Table'!W10 -> 32 | H93: ='Pivot Table'!X10 -> 27 | I93: ='Pivot Table'!Y10 -> 25
C94: =C88 -> Action | D94: =D88 -> Comedy | E94: =E88 -> Documentary | F94: =F88 -> Drama | G94: =G88 -> Horror | H94: =H88 -> Romance | I94: =I88 -> Sci-Fi
B117: 4. Retention & Loyalty:
B158: 5. Payment Preferences & Regional Trends
